<robot name="cart">
  <material name="blue">
    <color rgba="0 0 0.8 0.5" />
  </material>
  <material name="black">
    <color rgba="0 0 0 1" />
  </material>
  <material name="white">
    <color rgba="1 1 1 1" />
  </material>
  <link name="cart_base">
    <visual>
      <geometry>
        <box size="7.62 4.064 2.032" />
      </geometry>
      <origin rpy="0 0 0" xyz="0 0 -0.0" />
      <material name="blue" />
    </visual>
    <collision>
      <geometry>
        <box size="7.62 4.064 2.032" />
      </geometry>
    </collision>
    <inertial>
      <origin rpy="0 0 0" xyz="0 0 0.0" />
      <mass value="18000.0" />
      <inertia ixx="1118.7074400000001" ixy="0.0" ixz="0.0" iyy="309.67679999999996" iyz="0.0" izz="932.9013600000001" />
    </inertial>
  </link>
  <link name="right_front_wheel">
    <visual>
      <geometry>
        <cylinder length="0.8999999999999999" radius="2.667" />
      </geometry>
      <origin rpy="0 1.57075 1.57075" xyz="0 0 0" />
      <material name="white" />
    </visual>
    <collision>
      <geometry>
        <cylinder length="0.8999999999999999" radius="2.667" />
      </geometry>
      <origin rpy="0 1.57075 1.57075" xyz="0 0 0" />
    </collision>
    <inertial>
      <origin rpy="0 0 0" xyz="0 0 0.0" />
      <mass value="3628.7400000000002" />
      <inertia ixx="66.97646157464999" ixy="0.0" ixz="0.0" iyy="66.97646157464999" iyz="0.0" izz="129.05412414929998" />
    </inertial>
  </link>
  <joint name="cart_to_right_front_wheel" type="revolute">
    <limit lower="-10000" upper="10000" effort="15" velocity="15" />
    <axis rpy="0 0 0" xyz="0 1 0" />
    <parent link="cart_base" />
    <child link="right_front_wheel" />
    <origin rpy="0 0 0" xyz="3.81 3.0220000000000002 -0.7815384615384614" />
  </joint>
  <link name="left_front_wheel">
    <visual>
      <geometry>
        <cylinder length="0.8999999999999999" radius="2.667" />
      </geometry>
      <origin rpy="0 1.57075 1.57075" xyz="0 0 0" />
      <material name="white" />
    </visual>
    <collision>
      <geometry>
        <cylinder length="0.8999999999999999" radius="2.667" />
      </geometry>
      <origin rpy="0 1.57075 1.57075" xyz="0 0 0" />
    </collision>
    <inertial>
      <origin rpy="0 0 0" xyz="0 0 0.0" />
      <mass value="3628.7400000000002" />
      <inertia ixx="66.97646157464999" ixy="0.0" ixz="0.0" iyy="66.97646157464999" iyz="0.0" izz="129.05412414929998" />
    </inertial>
  </link>
  <joint name="cart_to_left_front_wheel" type="revolute">
    <limit lower="-10000" upper="10000" effort="15" velocity="15" />
    <axis rpy="0 0 0" xyz="0 1 0" />
    <parent link="cart_base" />
    <child link="left_front_wheel" />
    <origin rpy="0 0 0" xyz="3.81 -3.0220000000000002 -0.7815384615384614" />
  </joint>
  <link name="right_back_wheel">
    <visual>
      <geometry>
        <cylinder length="0.8999999999999999" radius="2.667" />
      </geometry>
      <origin rpy="0 1.57075 1.57075" xyz="0 0 0" />
      <material name="white" />
    </visual>
    <collision>
      <geometry>
        <cylinder length="0.8999999999999999" radius="2.667" />
      </geometry>
      <origin rpy="0 1.57075 1.57075" xyz="0 0 0" />
    </collision>
    <inertial>
      <origin rpy="0 0 0" xyz="0 0 0.0" />
      <mass value="3628.7400000000002" />
      <inertia ixx="66.97646157464999" ixy="0.0" ixz="0.0" iyy="66.97646157464999" iyz="0.0" izz="129.05412414929998" />
    </inertial>
  </link>
  <joint name="cart_to_right_back_wheel" type="revolute">
    <limit lower="-10000" upper="10000" effort="15" velocity="15" />
    <axis rpy="0 0 0" xyz="0 1 0" />
    <parent link="cart_base" />
    <child link="right_back_wheel" />
    <origin rpy="0 0 0" xyz="-3.81 3.0220000000000002 -0.7815384615384614" />
  </joint>
  <link name="left_back_wheel">
    <visual>
      <geometry>
        <cylinder length="0.8999999999999999" radius="2.667" />
      </geometry>
      <origin rpy="0 1.57075 1.57075" xyz="0 0 0" />
      <material name="white" />
    </visual>
    <collision>
      <geometry>
        <cylinder length="0.8999999999999999" radius="2.667" />
      </geometry>
      <origin rpy="0 1.57075 1.57075" xyz="0 0 0" />
    </collision>
    <inertial>
      <origin rpy="0 0 0" xyz="0 0 0.0" />
      <mass value="3628.7400000000002" />
      <inertia ixx="66.97646157464999" ixy="0.0" ixz="0.0" iyy="66.97646157464999" iyz="0.0" izz="129.05412414929998" />
    </inertial>
  </link>
  <joint name="cart_to_left_back_wheel" type="revolute">
    <limit lower="-10000" upper="10000" effort="15" velocity="15" />
    <axis rpy="0 0 0" xyz="0 1 0" />
    <parent link="cart_base" />
    <child link="left_back_wheel" />
    <origin rpy="0 0 0" xyz="-3.81 -3.0220000000000002 -0.7815384615384614" />
  </joint>

  

  <link name="payload">
    <visual>
      <geometry>
        <box size="1.0 1.0 1.0" />
      </geometry>
      <material name="black" />
    </visual>
    <collision>
      <geometry>
        <box size="1.0 1.0 1.0" />
      </geometry>
    </collision>
    <inertial>
      <origin rpy="0 0 0" xyz="0 0 0.0" />
      <mass value="18000.0" />
      <inertia ixx="30.000000000000007" ixy="0.0" ixz="0.0" iyy="30.000000000000007" iyz="0.0" izz="30.000000000000007" />
    </inertial>
  </link>
  <joint name="payload" type="prismatic">
    <limit lower="-0.25" upper="0.25" effort="100" velocity="10" />
    <axis rpy="0 0 0" xyz="1 0 0" />
    <parent link="cart_base" />
    <child link="payload" />
    <origin rpy="0 0 0" xyz="0.0 0.0 1.5694736842105264" />
    
  </joint>

</robot>
